<?xml version='1.0'?>
<robot name="Barrett">
  <!-- zhenyu: add xyzrpy virtual joints between world and robot to represent base link transform [BEGIN] -->
    <link name="world" />
    <link name="virtual_link_x" />
    <joint name="virtual_joint_x" type="prismatic">
        <parent link="world" />
        <child link="virtual_link_x" />

        <origin rpy="0 0 0" xyz="0 0 0" />
        <axis xyz="1 0 0" />
        <limit effort="300" lower="-10" upper="10" velocity="2" />
    </joint>

    <link name="virtual_link_y" />
    <joint name="virtual_joint_y" type="prismatic">
        <parent link="virtual_link_x" />
        <child link="virtual_link_y" />

        <origin rpy="0 0 0" xyz="0 0 0" />
        <axis xyz="0 1 0" />
        <limit effort="300" lower="-10" upper="10" velocity="2" />
    </joint>

    <link name="virtual_link_z" />
    <joint name="virtual_joint_z" type="prismatic">
        <parent link="virtual_link_y" />
        <child link="virtual_link_z" />

        <origin rpy="0 0 0" xyz="0 0 0" />
        <axis xyz="0 0 1" />
        <limit effort="300" lower="-10" upper="10" velocity="2" />
    </joint>

    <link name="virtual_link_roll" />
    <joint name="virtual_joint_roll" type="revolute">
        <parent link="virtual_link_z" />
        <child link="virtual_link_roll" />

        <origin rpy="0 0 0" xyz="0 0 0" />
        <axis xyz="1 0 0" />
        <limit effort="100" velocity="100" lower="-6.283185" upper="6.283185" />
    </joint>

    <link name="virtual_link_pitch" />
    <joint name="virtual_joint_pitch" type="revolute">
        <parent link="virtual_link_roll" />
        <child link="virtual_link_pitch" />

        <origin rpy="0 0 0" xyz="0 0 0" />
        <axis xyz="0 1 0" />
        <limit effort="100" velocity="100" lower="-6.283185" upper="6.283185" />
    </joint>

    <link name="virtual_link_yaw" />
    <joint name="virtual_joint_yaw" type="revolute">
        <parent link="virtual_link_pitch" />
        <child link="virtual_link_yaw" />

        <origin rpy="0 0 0" xyz="0 0 0" />
        <axis xyz="0 0 1" />
        <limit effort="100" velocity="100" lower="-6.283185" upper="6.283185" />
    </joint>

    <joint name="virtual_robot" type="fixed">
        <parent link="virtual_link_yaw" />
        <child link="palm" />
        <origin rpy="0 0 0" xyz="0 0 0" />
    </joint>
    <!-- zhenyu: add xyzrpy virtual joints between world and robot to represent base link transform [END] -->

  <link name="palm">
    <visual>
      <geometry>
        <mesh filename="./meshes/palm.stl" scale="0.00100000 0.00100000 0.00100000"/>
      </geometry>
    </visual>
    <collision>
      <geometry>
        <mesh filename="./meshes/palm.stl" scale="0.00100000 0.00100000 0.00100000"/>
      </geometry>
    </collision>
  </link>


  <link name="a_link1">
    <visual>
      <geometry>
        <mesh filename="./meshes/link1.stl" scale="0.00100000 0.00100000 0.00100000"/>
      </geometry>
    </visual>
    <collision>
      <geometry>
        <mesh filename="./meshes/link1.stl" scale="0.00100000 0.00100000 0.00100000"/>
      </geometry>
    </collision>
  </link>
  <link name="a_link2">
    <visual>
      <geometry>
        <mesh filename="./meshes/link2.stl" scale="0.00100000 0.00100000 0.00100000"/>
      </geometry>
    </visual>
    <collision>
      <geometry>
        <mesh filename="./meshes/link2.stl" scale="0.00100000 0.00100000 0.00100000"/>
      </geometry>
    </collision>
  </link>
  <link name="a_link3">
    <visual>
      <geometry>
        <mesh filename="./meshes/link3.stl" scale="0.00100000 0.00100000 0.00100000"/>
      </geometry>
    </visual>

    <collision>
      <geometry>
        <mesh filename="./meshes/link3.stl" scale="0.00100000 0.00100000 0.00100000"/>
      </geometry>
    </collision>
  </link>


  <link name="a_link1_joint"/>
  <joint name="a_palm_link1_joint" type="revolute">
    <origin rpy="0.00000000 3.14159265 0.00000000" xyz="0.02500000 0.00000000 -0.00100000"/>
    <parent link="palm"/>
    <child link="a_link1_joint"/>
    <axis xyz="0.00000000 0.00000000 1.00000000"/>
    <limit effort="30" lower="0.0" upper="3.14159265359" velocity="18.2"/>
  </joint>
  <link name="a_link1_dh"/>
  <joint name="a_link1_joint_link1_dh" type="fixed">
    <origin rpy="0.00000000 0.00000000 1.57079633"/>
    <parent link="a_link1_joint"/>
    <child link="a_link1_dh"/>
  </joint>
  <joint name="a_link1_dh_link1" type="fixed">
    <origin rpy="-1.57079633 0.00000000 0.00000000" xyz="0.05000000 0.00000000 0.00000000"/>
    <parent link="a_link1_dh"/>
    <child link="a_link1"/>
  </joint>

  <link name="a_link2_joint"/>
  <joint name="a_link1_link2_joint" type="revolute">
    <origin rpy="0.00000000 0.00000000 0.00000000" xyz="0.00000000 0.00000000 0.00000000"/>
    <parent link="a_link1"/>
    <child link="a_link2_joint"/>
    <axis xyz="0.00000000 0.00000000 1.00000000"/>
    <limit effort="30" lower="0.0" upper="2.51327412287" velocity="18.2"/>
  </joint>
  <link name="a_link2_dh"/>
  <joint name="a_link2_joint_link2_dh" type="fixed">
    <origin rpy="0.00000000 0.00000000 0.08726646"/>
    <parent link="a_link2_joint"/>
    <child link="a_link2_dh"/>
  </joint>
  <joint name="a_link2_dh_link2" type="fixed">
    <origin rpy="0.00000000 0.00000000 0.00000000" xyz="0.07000000 0.00000000 0.00000000"/>
    <parent link="a_link2_dh"/>
    <child link="a_link2"/>
  </joint>

  <link name="a_link3_joint"/>
  <joint name="a_link2_link3_joint" type="revolute">
    <origin rpy="0.00000000 0.00000000 0.00000000" xyz="0.00000000 0.00000000 0.00000000"/>
    <parent link="a_link2"/>
    <child link="a_link3_joint"/>
    <axis xyz="0.00000000 0.00000000 0.33333333"/>
    <limit effort="30" lower="0.0" upper="2.51327412287" velocity="18.2"/>
  </joint>
  <link name="a_link3_dh"/>
  <joint name="a_link3_joint_link3_dh" type="fixed">
    <origin rpy="0.00000000 0.00000000 0.69813170"/>
    <parent link="a_link3_joint"/>
    <child link="a_link3_dh"/>
  </joint>
  <joint name="a_link3_dh_link3" type="fixed">
    <origin rpy="0.00000000 0.00000000 0.00000000" xyz="0.05500000 0.00000000 0.00000000"/>
    <parent link="a_link3_dh"/>
    <child link="a_link3"/>
  </joint>



  <link name="b_link1">
    <visual>
      <geometry>
        <mesh filename="./meshes/link1.stl" scale="0.00100000 0.00100000 0.00100000"/>
      </geometry>
    </visual>
    <collision>
      <geometry>
        <mesh filename="./meshes/link1.stl" scale="0.00100000 0.00100000 0.00100000"/>
      </geometry>
    </collision>
  </link>
  <link name="b_link2">
    <visual>
      <geometry>
        <mesh filename="./meshes/link2.stl" scale="0.00100000 0.00100000 0.00100000"/>
      </geometry>
    </visual>

    <collision>
      <geometry>
        <mesh filename="./meshes/link2.stl" scale="0.00100000 0.00100000 0.00100000"/>
      </geometry>
    </collision>
  </link>
  <link name="b_link3">
    <visual>
      <geometry>
        <mesh filename="./meshes/link3.stl" scale="0.00100000 0.00100000 0.00100000"/>
      </geometry>
    </visual>

    <collision>
      <geometry>
        <mesh filename="./meshes/link3.stl" scale="0.00100000 0.00100000 0.00100000"/>
      </geometry>
    </collision>
  </link>
  <link name="b_link1_joint"/>
  <joint name="b_palm_link1_joint" type="revolute">
    <origin rpy="0.00000000 0.00000000 0.00000000" xyz="-0.02500000 0.00000000 -0.00100000"/>
    <parent link="palm"/>
    <child link="b_link1_joint"/>
    <axis xyz="0.00000000 0.00000000 1.00000000"/>
    <limit effort="30" lower="0.0" upper="3.14159265359" velocity="18.2"/>
  </joint>
  <link name="b_link1_dh"/>
  <joint name="b_link1_joint_link1_dh" type="fixed">
    <origin rpy="0.00000000 0.00000000 1.57079633"/>
    <parent link="b_link1_joint"/>
    <child link="b_link1_dh"/>
  </joint>
  <joint name="b_link1_dh_link1" type="fixed">
    <origin rpy="1.57079633 0.00000000 0.00000000" xyz="0.05000000 0.00000000 0.00000000"/>
    <parent link="b_link1_dh"/>
    <child link="b_link1"/>
  </joint>
  <link name="b_link2_joint"/>
  <joint name="b_link1_link2_joint" type="revolute">
    <origin rpy="0.00000000 0.00000000 0.00000000" xyz="0.00000000 0.00000000 0.00000000"/>
    <parent link="b_link1"/>
    <child link="b_link2_joint"/>
    <axis xyz="0.00000000 0.00000000 1.00000000"/>
    <limit effort="30" lower="0.0" upper="2.51327412287" velocity="18.2"/>
  </joint>
  <link name="b_link2_dh"/>
  <joint name="b_link2_joint_link2_dh" type="fixed">
    <origin rpy="0.00000000 0.00000000 0.08726646"/>
    <parent link="b_link2_joint"/>
    <child link="b_link2_dh"/>
  </joint>
  <joint name="b_link2_dh_link2" type="fixed">
    <origin rpy="0.00000000 0.00000000 0.00000000" xyz="0.07000000 0.00000000 0.00000000"/>
    <parent link="b_link2_dh"/>
    <child link="b_link2"/>
  </joint>
  <link name="b_link3_joint"/>
  <joint name="b_link2_link3_joint" type="revolute">
    <origin rpy="0.00000000 0.00000000 0.00000000" xyz="0.00000000 0.00000000 0.00000000"/>
    <parent link="b_link2"/>
    <child link="b_link3_joint"/>
    <axis xyz="0.00000000 0.00000000 0.33333333"/>
    <limit effort="30" lower="0.0" upper="2.51327412287" velocity="18.2"/>
  </joint>
  <link name="b_link3_dh"/>
  <joint name="b_link3_joint_link3_dh" type="fixed">
    <origin rpy="0.00000000 0.00000000 0.69813170"/>
    <parent link="b_link3_joint"/>
    <child link="b_link3_dh"/>
  </joint>
  <joint name="b_link3_dh_link3" type="fixed">
    <origin rpy="0.00000000 0.00000000 0.00000000" xyz="0.05500000 0.00000000 0.00000000"/>
    <parent link="b_link3_dh"/>
    <child link="b_link3"/>
  </joint>



  <link name="c_link2">
    <visual>
      <geometry>
        <mesh filename="./meshes/link2.stl" scale="0.00100000 0.00100000 0.00100000"/>
      </geometry>
    </visual>

    <collision>
      <geometry>
        <mesh filename="./meshes/link2.stl" scale="0.00100000 0.00100000 0.00100000"/>
      </geometry>
    </collision>
  </link>

  <link name="c_link3">
    <visual>
      <geometry>
        <mesh filename="./meshes/link3.stl" scale="0.00100000 0.00100000 0.00100000"/>
      </geometry>
    </visual>

    <collision>
      <geometry>
        <mesh filename="./meshes/link3.stl" scale="0.00100000 0.00100000 0.00100000"/>
      </geometry>
    </collision>
  </link>

  <link name="c_link2_joint"/>

  <!-- DUMMY LINK FOR THE CONSECUTIVE Z ROTATION -->
  <link name="c_link2_joint_0"/>

  <joint name="c_palm_link2_joint_0" type="revolute">
    <origin rpy="0.00000000 -1.57079633 0" xyz="0.00000000 -0.05000000 -0.00100000"/>
    <parent link="palm"/>
    <child link="c_link2_joint_0"/>
    <axis xyz="0.00000000 0.00000000 1.00000000"/>
    <limit effort="30" lower="0.0" upper="2.51327412287" velocity="18.2"/>
  </joint>

  <!-- DUMMY Fixed joint FOR THE CONSECUTIVE Z ROTATION -->
  <joint name="c_link2_joint_0_link2_joint" type="fixed">
    <origin rpy="0.00000000 0 -1.57079633" xyz="0.00000000 0.00000000 0.0000000"/>
    <parent link="c_link2_joint_0"/>
    <child link="c_link2_joint"/>
    <axis xyz="0.00000000 0.00000000 1.00000000"/>
  </joint>

  <link name="c_link2_dh"/>
  <joint name="c_link2_joint_link2_dh" type="fixed">
    <origin rpy="0.00000000 0.00000000 0.08726646"/>
    <parent link="c_link2_joint"/>
    <child link="c_link2_dh"/>
  </joint>

  <joint name="c_link2_dh_link2" type="fixed">
    <origin rpy="0.00000000 0.00000000 0.00000000" xyz="0.07000000 0.00000000 0.00000000"/>
    <parent link="c_link2_dh"/>
    <child link="c_link2"/>
  </joint>

  <link name="c_link3_joint"/>

  <joint name="c_link2_link3_joint" type="revolute">
    <origin rpy="0.00000000 0.00000000 0.00000000" xyz="0.00000000 0.00000000 0.00000000"/>
    <parent link="c_link2"/>
    <child link="c_link3_joint"/>
    <axis xyz="0.00000000 0.00000000 0.33333333"/>
    <limit effort="30" lower="0.0" upper="2.51327412287" velocity="18.2"/>
  </joint>
  <link name="c_link3_dh"/>

  <joint name="c_link3_joint_link3_dh" type="fixed">
    <origin rpy="0.00000000 0.00000000 0.69813170"/>
    <parent link="c_link3_joint"/>
    <child link="c_link3_dh"/>
  </joint>
  <joint name="c_link3_dh_link3" type="fixed">
    <origin rpy="0.00000000 0.00000000 0.00000000" xyz="0.05500000 0.00000000 0.00000000"/>
    <parent link="c_link3_dh"/>
    <child link="c_link3"/>
  </joint>

</robot>
